Workbook

Sheet Parámetros de Proceso
B2: Tº | C2: 1 | D2: 2 | E2: 3 | F2: 4 | G2: 5
A3: FECHA: | B3: Agua
B4: Harina
B5: Ambiente
A6: FORMULACION
A7: Harina Base (g): | C7: ='1-Actual'!B5 -> 1 | D7: ='2-Actual Proceso'!B5 -> 1 | E7: ='3-Actual Proceso y ajuste F'!B5 -> 1 | F7: ='4-Formulacion Productos existen'!B5 -> 1 | G7: ='5-Formulacion 3'!B5 -> 1
A8: Sal (g): | C8: ='1-Actual'!B6 -> 0.018 | D8: ='2-Actual Proceso'!B6 -> 0.018 | E8: ='3-Actual Proceso y ajuste F'!B6 -> 0.018 | F8: ='4-Formulacion Productos existen'!B6 -> 0.018 | G8: ='5-Formulacion 3'!B6 -> 0.02
A9: Levadura: | C9: ='1-Actual'!B7 -> 0.025 | D9: ='2-Actual Proceso'!B7 -> 0.025 | E9: ='3-Actual Proceso y ajuste F'!B7 -> 0.025 | F9: ='4-Formulacion Productos existen'!B7 -> 0.025 | G9: ='5-Formulacion 3'!B7 -> 0.025
A10: Agua 1 | C10: ='1-Actual'!B8 -> 0.51 | D10: ='2-Actual Proceso'!B8 -> 0.51 | E10: ='3-Actual Proceso y ajuste F'!B8 -> 0.54 | F10: ='4-Formulacion Productos existen'!B8 -> 0.54 | G10: ='5-Formulacion 3'!B8 -> 0.54
A13: AMASADO
A14: Tiempo Vel. 1
A15: Tiempo Vel. 2
A16: Tempertaura Final
A17: ARMADO
A18: Peso Pieza
A20: DESCANSO
A21: Tiempo (min.)
A22: FERMENTACION
A23: Inicio
A24: Fin
A25: Total
... A30: ASPECTO

Sheet Fotos
B2: Registro Fotográfico de Ensayos
B5: Nº de Ensayo | C5: Fecha | D5: Producto | E5: Formulación | F5: Foto: Amasado | G5: Foto: Crudo | H5: Foto: Horneado | I5: Observaciones

Sheet Análisis Reológico
A1: Propiedad | B1: Unidad
A2: Humedad | B2: %
A3: Gluten Húmedo | B3: %
A4: W (Fuerza)
A5: Relación P/L
A6: Cenizas | B6: %
A7: Gluten Seco | B7: %
A8: Gluten Index
A9: Falling Number | B9: s
A10: Tenacidad (P)
A11: Extensibilidad (L) | B11: mm
A12: Daño Almidón | B12: %

Sheet 1-Actual
A1: Producto | B1: Pan de Miga | E1: 3
A2: FECHA:
A4: Receta | B4: % | E4: Peso Ensayo grs
A5: Harina Inglesera Mol Arg | B5: 1 | E5: 100000 | F5: FALSE
A6: Sal fina | B6: 0.018 | E6: =$E$5*B6 -> 1800 | F6: FALSE
A7: Levadura Fresca | B7: 0.025 | E7: =$E$5*B7 -> 2500 | F7: FALSE
A8: Agua | B8: 0.51 | E8: =$E$5*B8 -> 51000 | F8: FALSE
A10: Aditivos | B10: grs/100kg
A11: Alfa A 100.000 skb danisco | B11: 15 | E11: =(B11/$E$5)*$E$5 -> 15 | F11: FALSE
A12: Almidón pregel Bufallo | B12: 260 | C12: =IFERROR(VLOOKUP(A12,Datos!$B$3:$C$52,2,FALSE),"") | E12: =(B12/$E$5)*$E$5 -> 260 | F12: FALSE
A13: Propionato de calcio | B13: 200 | C13: =IFERROR(VLOOKUP(A13,Datos!$B$3:$C$52,2,FALSE),"") | E13: =(B13/$E$5)*$E$5 -> 200 | F13: FALSE
A14: Granozyme AFH | B14: 40 | C14: =IFERROR(VLOOKUP(A14,Datos!$B$3:$C$52,2,FALSE),"") | E14: =(B14/$E$5)*$E$5 -> 40 | F14: FALSE
A15: Azucar comun | B15: 200 | C15: =IFERROR(VLOOKUP(A15,Datos!$B$3:$C$52,2,FALSE),"") | D15: =(C15/1000)*B15 -> 0 | E15: =(B15/$E$5)*$E$5 -> 200 | F15: FALSE
A16: L-Cisteina | B16: 1.5 | C16: =IFERROR(VLOOKUP(A16,Datos!$B$3:$C$52,2,FALSE),"") -> 38 | D16: =(C16/1000)*B16 -> 0.057 | E16: =(B16/$E$5)*$E$5 -> 1.5 | F16: FALSE
A17: Sub total Aditivos | B17: =SUM(B11:B16) -> 716.5 | D17: =SUM(D11:D16) -> 0.057
A18: Mejorador
A19: MejorMiga Calsa | B19: 0.015 | D19: =(C19/1000)*B19 -> 0 | E19: =B19*$E$5 -> 1500 | F19: FALSE
E20: =(B20/25000)*$E$5 -> 0 | F20: FALSE
F21: FALSE
A22: Sub total Mejorador | B22: =SUM(B19:B21) -> 0.015 | D22: =SUM(D19:D21) -> 0
E23: =SUM(E5:E21) -> 157516.5

Sheet 2-Actual Proceso
A1: Producto | B1: Pan de Miga | E1: 3
A2: FECHA:
A4: Receta | B4: % | E4: Peso Ensayo grs
A5: Harina Inglesera Mol Arg | B5: 1 | E5: 100000 | F5: FALSE
A6: Sal fina | B6: 0.018 | E6: =$E$5*B6 -> 1800 | F6: FALSE
A7: Levadura Fresca | B7: 0.025 | E7: =$E$5*B7 -> 2500 | F7: FALSE
A8: Agua | B8: 0.51 | E8: =$E$5*B8 -> 51000 | F8: FALSE
A10: Aditivos | B10: grs/100kg
A11: Alfa A 100.000 skb danisco | B11: 15 | E11: =(B11/$E$5)*$E$5 -> 15 | F11: FALSE
A12: Almidón pregel Bufallo | B12: 260 | C12: =IFERROR(VLOOKUP(A12,Datos!$B$3:$C$52,2,FALSE),"") | E12: =(B12/$E$5)*$E$5 -> 260 | F12: FALSE
A13: Propionato de calcio | B13: 200 | C13: =IFERROR(VLOOKUP(A13,Datos!$B$3:$C$52,2,FALSE),"") | E13: =(B13/$E$5)*$E$5 -> 200 | F13: FALSE
A14: Granozyme AFH | B14: 40 | C14: =IFERROR(VLOOKUP(A14,Datos!$B$3:$C$52,2,FALSE),"") | E14: =(B14/$E$5)*$E$5 -> 40 | F14: FALSE
A15: Azucar comun | B15: 200 | C15: =IFERROR(VLOOKUP(A15,Datos!$B$3:$C$52,2,FALSE),"") | D15: =(C15/1000)*B15 -> 0 | E15: =(B15/$E$5)*$E$5 -> 200 | F15: FALSE
A16: L-Cisteina | B16: 1.5 | C16: =IFERROR(VLOOKUP(A16,Datos!$B$3:$C$52,2,FALSE),"") -> 38 | D16: =(C16/1000)*B16 -> 0.057 | E16: =(B16/$E$5)*$E$5 -> 1.5 | F16: FALSE
A17: Sub total Aditivos | B17: =SUM(B11:B16) -> 716.5 | D17: =SUM(D11:D16) -> 0.057
A18: Mejorador
A19: MejorMiga Calsa | D19: =(C19/1000)*B19 -> 0 | E19: =B19*$E$5 -> 0 | F19: FALSE
E20: =(B20/25000)*$E$5 -> 0 | F20: FALSE
F21: FALSE
A22: Sub total Mejorador | B22: =SUM(B19:B21) -> 0 | D22: =SUM(D19:D21) -> 0
E23: =SUM(E5:E21) -> 156016.5

Sheet 3-Actual Proceso y ajuste F
A1: Producto | E1: 1
A2: FECHA:
A4: Receta | B4: % | E4: Peso Ensayo grs
A5: Harina Inglesera Mol Arg | B5: 1 | E5: 100000 | F5: FALSE
A6: Sal fina | B6: 0.018 | E6: =$E$5*B6 -> 1800 | F6: FALSE
A7: Levadura Fresca | B7: 0.025 | E7: =$E$5*B7 -> 2500 | F7: FALSE
A8: Agua | B8: 0.54 | E8: =$E$5*B8 -> 54000 | F8: FALSE
B9: grs/kg
A10: Aditivos | B10: C
A11: Alfa A 100.000 skb danisco | B11: 0.5 | C11: =IFERROR(VLOOKUP(A11,Datos!$B$3:$C$52,2,FALSE),"") | D11: =(C11/1000)*B11 -> 0 | E11: =(B11/$E$5)*$E$5 -> 0.5 | F11: FALSE
A12: Almidón pregel Bufallo | B12: 260 | C12: =IFERROR(VLOOKUP(A12,Datos!$B$3:$C$52,2,FALSE),"") | D12: =(C12/1000)*B12 -> 0 | E12: =(B12/$E$5)*$E$5 -> 260 | F12: FALSE
A13: Propionato de calcio | B13: 200 | C13: =IFERROR(VLOOKUP(A13,Datos!$B$3:$C$52,2,FALSE),"") | D13: =(C13/1000)*B13 -> 0 | E13: =(B13/$E$5)*$E$5 -> 200 | F13: FALSE
A14: Granozyme AFH | B14: 15 | C14: =IFERROR(VLOOKUP(A14,Datos!$B$3:$C$52,2,FALSE),"") | D14: =(C14/1000)*B14 -> 0 | E14: =(B14/$E$5)*$E$5 -> 15 | F14: FALSE
A15: Azucar comun | B15: 0 | C15: =IFERROR(VLOOKUP(A15,Datos!$B$3:$C$52,2,FALSE),"") | D15: =(C15/1000)*B15 -> 0 | E15: =(B15/$E$5)*$E$5 -> 0 | F15: FALSE
A16: L-Cisteina | B16: 1.5 | C16: =IFERROR(VLOOKUP(A16,Datos!$B$3:$C$52,2,FALSE),"") -> 38 | D16: =(C16/1000)*B16 -> 0.057 | E16: =(B16/$E$5)*$E$5 -> 1.5 | F16: FALSE
A17: Sub total Aditivos | B17: =SUM(B11:B16) -> 477 | D17: =SUM(D11:D16) -> 0.057
A18: Mejorador
C19: =IFERROR(VLOOKUP(A19,Datos!$B$3:$C$52,2,FALSE),"") | D19: =(C19/1000)*B19 -> 0 | E19: =(B19/25000)*$E$5 -> 0 | F19: FALSE
E20: =(B20/25000)*$E$5 -> 0 | F20: FALSE
F21: FALSE
A22: Sub total Mejorador | B22: =SUM(B19:B21) -> 0 | D22: =SUM(D19:D21) -> 0
E23: =SUM(E5:E21) -> 158777

Sheet 4-Formulacion Productos existen
A1: Producto | B1: PAN FRANCES | E1: 2
A2: FECHA:
A4: Receta | B4: % | E4: Peso Ensayo grs
A5: Harina Inglesera Mol Arg | B5: 1 | E5: 100000 | F5: FALSE
A6: Sal fina | B6: 0.018 | E6: =$E$5*B6 -> 1800 | F6: FALSE
A7: Levadura Fresca | B7: 0.025 | E7: =$E$5*B7 -> 2500 | F7: FALSE
A8: Agua | B8: 0.54 | E8: =$E$5*B8 -> 54000 | F8: FALSE
A10: Aditivos | B10: grs/100 kg | C10: $/kg | D10: Costo dosis
A11: SuperGluten | B11: 200 | C11: =IFERROR(VLOOKUP(A11,Datos!$B$3:$C$52,2,FALSE),"") | D11: =(C11/1000)*B11 -> 0 | E11: =(B11/$E$5)*$E$5 -> 200 | F11: FALSE
C12: =IFERROR(VLOOKUP(A12,Datos!$B$3:$C$52,2,FALSE),"") | D12: =(C12/1000)*B12 -> 0 | E12: =(B12/$E$5)*$E$5 -> 0 | F12: FALSE
A13: Granozyme AFH | B13: 12 | C13: =IFERROR(VLOOKUP(A13,Datos!$B$3:$C$52,2,FALSE),"") | D13: =(C13/1000)*B13 -> 0 | E13: =(B13/$E$5)*$E$5 -> 12 | F13: FALSE
A14: L-Cisteina | B14: 2 | C14: =IFERROR(VLOOKUP(A14,Datos!$B$3:$C$52,2,FALSE),"") -> 38 | D14: =(C14/1000)*B14 -> 0.076 | E14: =(B14/$E$5)*$E$5 -> 2 | F14: FALSE
C15: =IFERROR(VLOOKUP(A15,Datos!$B$3:$C$52,2,FALSE),"") | D15: =(C15/1000)*B15 -> 0 | E15: =(B15/$E$5)*$E$5 -> 0 | F15: FALSE
C16: =IFERROR(VLOOKUP(A16,Datos!$B$3:$C$52,2,FALSE),"") | D16: =(C16/1000)*B16 -> 0 | E16: =(B16/$E$5)*$E$5 -> 0 | F16: FALSE
A17: Sub total Aditivos | B17: =SUM(B11:B16) -> 214 | D17: =SUM(D11:D16) -> 0.076
A18: Mejorador
D19: =(C19/1000)*B19 -> 0 | E19: =(B19/25000)*$E$5 -> 0 | F19: FALSE
E20: =(B20/25000)*$E$5 -> 0 | F20: FALSE
F21: FALSE
A22: Sub total Mejorador | B22: =SUM(B19:B21) -> 0 | D22: =SUM(D19:D21) -> 0

Sheet 5-Formulacion 3
A1: Producto | B1: PAN FRANCES | E1: 1
A2: FECHA:
A4: Receta | B4: % | E4: Peso Ensayo grs
A5: Harina 000 SA | B5: 1 | E5: 1000 | F5: FALSE
A6: Sal fina | B6: 0.02 | E6: =$E$5*B6 -> 20 | F6: FALSE
A7: Levadura Fresca | B7: 0.025 | E7: =$E$5*B7 -> 25 | F7: FALSE
A8: Agua | B8: 0.54 | E8: =$E$5*B8 -> 540 | F8: FALSE
A10: Aditivos | B10: grs/100 kg | C10: $/kg | D10: Costo dosis
A11: Acido ascorbico | C11: =IFERROR(VLOOKUP(A11,Datos!$B$3:$C$52,2,FALSE),"") -> 6.3 | D11: =(C11/1000)*B11 -> 0 | E11: =(B11/25000)*$E$5 -> 0 | F11: FALSE
A12: Monozyme Gluten Booster | C12: =IFERROR(VLOOKUP(A12,Datos!$B$3:$C$52,2,FALSE),"") -> 35.3 | D12: =(C12/1000)*B12 -> 0 | E12: =(B12/25000)*$E$5 -> 0 | F12: FALSE
A13: Monozyme GR5 | C13: =IFERROR(VLOOKUP(A13,Datos!$B$3:$C$52,2,FALSE),"") -> 38.4 | D13: =(C13/1000)*B13 -> 0 | E13: =(B13/25000)*$E$5 -> 0 | F13: FALSE
A14: L-Cisteina | C14: =IFERROR(VLOOKUP(A14,Datos!$B$3:$C$52,2,FALSE),"") -> 38 | D14: =(C14/1000)*B14 -> 0 | E14: =(B14/25000)*$E$5 -> 0 | F14: FALSE
C15: =IFERROR(VLOOKUP(A15,Datos!$B$3:$C$52,2,FALSE),"") | D15: =(C15/1000)*B15 -> 0 | E15: =(B15/25000)*$E$5 -> 0 | F15: FALSE
C16: =IFERROR(VLOOKUP(A16,Datos!$B$3:$C$52,2,FALSE),"") | D16: =(C16/1000)*B16 -> 0 | E16: =(B16/25000)*$E$5 -> 0 | F16: FALSE
A17: Sub total Aditivos | B17: =SUM(B11:B16) -> 0 | D17: =SUM(D11:D16) -> 0
A18: Mejorador
D19: =(C19/1000)*B19 -> 0 | E19: =(B19/25000)*$E$5 -> 0 | F19: FALSE
E20: =(B20/25000)*$E$5 -> 0 | F20: FALSE
F21: FALSE
A22: Sub total Mejorador | B22: =SUM(B19:B21) -> 0 | D22: =SUM(D19:D21) -> 0

Sheet Datos
B2: Producto | C2: Precios x kg | D2: Proveedor
B3: Acido ascorbico | C3: 6.3
B4: Ada 23% | C4: 4.7
B5: Ada 99%
B6: Agua | C6: 0
B7: Alfa A 100.000 skb danisco
B8: Almidón pregel Bufallo
B9: Azucar comun
B10: Calsa MAX | C10: 21.8
B11: Calsa MejorMiga
B12: Formula 1 | C12: 12
B13: Gluten vital | C13: 3.6
B14: Granoplus 35 | C14: 24.5
B15: Granoplus concetrate | C15: 11
B16: Granoplus frescura
B17: Granoplus Magic | C17: 8.6
B18: Granozyme A2H | C18: 17.8
B19: Granozyme AFH
B20: Granozyme EM-I | C20: 16 | J20: Almidón pregel
B21: Granozyme HLG | C21: 37 | J21: Propionato de calcio
B22: Harina 000 CA | C22: 0 | J22: Azúcar
B23: Harina 000 SA | C23: 0 | J23: Granozyme AFH
B24: Harina 000 SL | C24: 0 | J24: Alfa A 100.000 skb danisco
B25: Harina 0000 CA | C25: 0
B26: Harina 0000 SA | C26: 0
B27: Harina Inglesera AM
B28: Harina Inglesera Cabodi
B29: Harina Inglesera Lago
B30: Harina Inglesera Mol Arg
B31: L-Cisteina | C31: 38
B32: Levadura Fresca
B33: Levadura prensada | C33: 4.2
B34: Levadura seca | C34: 10
B35: Levamix AL | C35: 3.81
B36: MGD 90%
B37: SSL
B38: Materia grasa | C38: 4
B39: MejorMiga Calsa
B40: Monozyme 2078 | C40: 17.8
B41: Monozyme Balance | C41: 32
...
